Workbook

Sheet Analisis de Mercado
B4: Analisis de Mercado | D4: Observación
B5: Mercado Potencial | C5: 2242 | D5: instituciones publicas y privadas | J5: =C12*(C13*C13)*C14*C15 -> 618.75
B6: Mercado Objetivo | C6: 1846 | D6: Colegios Privados | J6: =((C16*C16)*(C12-1))+((C13*C13)*C14*C15) -> 14.1012
B7: Nicho | C7: 44 | D7: Colegios Privados puente aranda
B11: Calculo de la Muestra
B12: Tamaño de Población | C12: =C7 -> 44
B13: Nivel de Confianza | C13: 7.5
B14: Probabilidad de Ejecucion | C14: 0.5 | G14: Nivel de Confianza | I14: Error
B15: Probabilidad de No Ejecucion | C15: 0.5 | G15: 0.95 | H15: 7.5 | I15: 0.03
B16: Margen de Error | C16: 0.03 | G16: 0.99 | H16: 9.5 | I16: 0.01
B18: Tamaño de la Muestra | C18: =J5/J6 -> 43.879244

Sheet Estructura de Mercado
B4: Nombre de la Empresa | C4: Asistente
B6: Estructura del Mercado por Unidades
B7: Producto | C7: Clientes Potenciales | D7: Habitos de Consumo Cliente | E7: Ventas Mensuales | F7: Participacion en el Mercado | G7: Ventas Anuales
B8: Asistnte | C8: ='Analisis de Mercado'!C7 -> 44 | D8: 1 | E8: 1 | F8: =G8/(C8*D8) -> 0.27272727 | G8: =E8*12 -> 12
B12: Totales | C12: =SUM(C8:C11) -> 44 | D12: =SUM(D8:D11) -> 1 | E12: =SUM(E8:E11) -> 1 | F12: =SUM(F8:F11) -> 0.27272727 | G12: =SUM(G8:G11) -> 12

Sheet Datos Economicos
C4: Ventas Anules por Producto
C5: Producto | D5: Unidades a Vender en el Año | E5: Precio Unitario | F5: Ventas Totales año 1
C6: ='Estructura de Mercado'!B8 -> Asistnte | D6: 22 | E6: 2000000 | F6: =E6*D6 -> 44000000
C7: ='Estructura de Mercado'!B9 | D7: ='Estructura de Mercado'!G9 | F7: =E7*D7 -> 0
C8: ='Estructura de Mercado'!B10 | D8: ='Estructura de Mercado'!G10 | F8: =E8*D8 -> 0
C9: ='Estructura de Mercado'!B11 | D9: ='Estructura de Mercado'!G11 | F9: =E9*D9 -> 0
C16: Datos Economicos
C17: Indicadores | D17: Año 1 | E17: Año 2 | F17: Año 3 | G17: Año 4 | H17: Año 5
C18: Inflación | D18: 0.035 | E18: 0.037 | F18: 0.031 | G18: 0.037 | H18: 0.031
C19: D.T.F | D19: 0.0229 | E19: 0.0316 | F19: 0.0405 | G19: 0.0463 | H19: 0.0514
C20: I.P.C | D20: 0.035 | E20: 0.035 | F20: 0.037 | G20: 0.032 | H20: 0.031
C21: I.P.P | D21: 0.035 | E21: 0.035 | F21: 0.037 | G21: 0.032 | H21: 0.031
C22: P.I.B | D22: 0.036 | E22: 0.034 | F22: 0.032 | G22: 0.032 | H22: 0.031

Sheet ParaFiscales
B3: Nomina
B4: Salario Minimo | C4: 1750905
B5: Auxilio de Transporte | C5: 249095
B6: Salario Minimo Integral | C6: 22761765
B7: Aportes Fiscales
B8: SENA | C8: 0.02
B9: ICBF | C9: 0.03
B10: Cajas | C10: 0.04
B11: Total | C11: =SUM(C8:C10) -> 0.09
B12: Cargas Prestacionales
B13: Cesantias | C13: 0.0833
B14: Intereses a las Cesantias | C14: 0.01
B15: Prima de Servicios | C15: 0.0833
B16: Vacaciones | C16: 0.0417
B17: Total | C17: =SUM(C13:C16) -> 0.2183
B18: Seguridad Social
B19: Salud
B20: Empresa | C20: 0.085
B21: Empleado | C21: 0.04
B22: Pension
B23: Empresa | C23: 0.12
B24: Empleado | C24: 0.04
B25: Total Empresa | C25: =SUM(C20+C23) -> 0.205
B26: Total Empleado | C26: =SUM(C21+C24) -> 0.08
B27: Totales | C27: =SUM(C11+C17+C25) -> 0.5133

Sheet Gastos de Constitución
B4: Registro Mercantil
B5: Concepto | C5: Unidad | D5: Valor | E5: Total
E6: =C6*D6 -> 0
E7: =C7*D7 -> 0
E8: =C8*D8 -> 0
E9: =C9*D9 -> 0
E10: =C10*D10 -> 0
B11: Total | D11: =SUM(D6:D10) -> 0 | E11: =SUM(E6:E10) -> 0
B14: Permisos y Licencias
B15: Concepto | C15: Unidad | D15: Valor | E15: Total
E16: =C16*D16 -> 0
E17: =C17*D17 -> 0
E18: =C18*D18 -> 0
E19: =C19*D19 -> 0
E20: =C20*D20 -> 0
B21: Total | D21: =SUM(D16:D20) -> 0 | E21: =SUM(E16:E20) -> 0

Sheet Plan de Inversion
B3: Activos Fijos | H3: Plan de Inversion | K3: Depreciaciones
B4: Descripcion | C4: Unidad Medida | D4: Cantidad | E4: Valor Unitario | F4: Total | H4: Activos Fijos | I4: =F9 -> 0 | K4: Concepto | L4: Valor total | M4: Vida Util | N4: Año 1 | O4: Año 2 | P4: Año 3 | Q4: Año 4 | R4: Año 5
F5: =D5*E5 -> 0 | H5: Adecuaciones | I5: =F18 -> 0 | K5: Adecuaciones | L5: =I5 -> 0 | M5: 20 | N5: =$L$5/$M$5 -> 0 | O5: =$L$5/$M$5 -> 0 | P5: =$L$5/$M$5 -> 0 | Q5: =$L$5/$M$5 -> 0 | R5: =$L$5/$M$5 -> 0
F6: =D6*E6 -> 0 | H6: Muebles y Enseres | I6: =F35 -> 1520232 | K6: Muebles y Enseres | L6: =I6 -> 1520232 | M6: 10 | N6: =$L$6/$M$6 -> 152023.2 | O6: =$L$6/$M$6 -> 152023.2 | P6: =$L$6/$M$6 -> 152023.2 | Q6: =$L$6/$M$6 -> 152023.2 | R6: =$L$6/$M$6 -> 152023.2
F7: =D7*E7 -> 0 | H7: Maquinaria y Equipo | I7: =F52 -> 6500000 | K7: Maquinaria y Equipo | L7: =I7 -> 6500000 | M7: 5 | N7: =$L$7/$M$7 -> 1300000 | O7: =$L$7/$M$7 -> 1300000 | P7: =$L$7/$M$7 -> 1300000 | Q7: =$L$7/$M$7 -> 1300000 | R7: =$L$7/$M$7 -> 1300000
F8: =D8*E8 -> 0 | H8: Total | I8: =SUM(I4:I7) -> 8020232 | K8: Total | L8: =SUM(L4:L7) -> 8020232 | N8: =SUM(N5:N7) -> 1452023.2 | O8: =SUM(O5:O7) -> 1452023.2 | P8: =SUM(P5:P7) -> 1452023.2 | Q8: =SUM(Q5:Q7) -> 1452023.2 | R8: =SUM(R5:R7) -> 1452023.2
B9: Total | F9: =SUM(F5:F8) -> 0
B12: Adecuaciones
B13: Descripcion | C13: Unidad Medida | D13: Cantidad | E13: Valor Unitario | F13: Total
F14: =D14*E14 -> 0
F15: =(D15*E15) -> 0
F16: =(D16*E16) -> 0
F17: =(D17*E17) -> 0
B18: Total | F18: =SUM(F14:F17) -> 0
B21: Muebles y Enseres
B22: Descripcion | C22: Unidad Medida | D22: Cantidad | E22: Valor Unitario | F22: Total
B23: Silla Para Oficina Ergonomica | C23: Unidad | D23: 3 | E23: 138900 | F23: =D23*E23 -> 416700
B24: Escritorio en L | C24: Unidad | D24: 3 | E24: 367844 | F24: =D24*E24 -> 1103532
F25: =D25*E25 -> 0
F26: =D26*E26 -> 0
F27: =D27*E27 -> 0
F28: =D28*E28 -> 0
F29: =D29*E29 -> 0
F30: =D30*E30 -> 0
F31: =D31*E31 -> 0
F32: =(D32*E32) -> 0
F33: =(D33*E33) -> 0
F34: =(D34*E34) -> 0
B35: Total | F35: =SUM(F23:F34) -> 1520232
B38: Maquinaria y Equipo
B39: Descripcion | C39: Unidad Medida | D39: Cantidad | E39: Valor Unitario | F39: Total
B40: Computador Escritorio | C40: Unidad | D40: 2 | E40: 2000000 | F40: =D40*E40 -> 4000000
B41: Portatil HP | C41: Unidad | D41: 1 | E41: 2500000 | F41: =D41*E41 -> 2500000
F42: =D42*E42 -> 0
F43: =D43*E43 -> 0
F44: =D44*E44 -> 0
F45: =D45*E45 -> 0
F46: =D46*E46 -> 0
F47: =D47*E47 -> 0
F48: =D48*E48 -> 0
...

Sheet Gastos de Personal
B3: Salario Personal | E3: Salud | H3: Pension | K3: Subsidio de Transporte | L3: Total Sin Descuentos | M3: Sueldo Total Año | N3: Por Hora
B4: Cargo | C4: Sueldo Mensual | D4: Dias Laborados | E4: Empleado | F4: Empresa | G4: Total | H4: Empleado | I4: Empresa | J4: Total | K4: Empleado | L4: Total
B5: Salario minimo | C5: 1750905 | D5: 30 | E5: =C5*ParaFiscales!$C$21 -> 70036.2 | F5: =C5*ParaFiscales!$C$20 -> 148826.92 | G5: =SUM(E5:F5) -> 218863.12 | H5: =C5*ParaFiscales!$C$24 -> 70036.2 | I5: =C5*ParaFiscales!$C$23 -> 210108.6 | J5: =SUM(H5:I5) -> 280144.8 | K5: 249095 | L5: =C5+K5 -> 2000000 | M5: =C5*12 -> 21010860 | N5: 10489.51
B6: Programador Junior | C6: 2000000 | D6: 30 | E6: =C6*ParaFiscales!$C$21 -> 80000 | F6: =C6*ParaFiscales!$C$20 -> 170000 | G6: =SUM(E6:F6) -> 250000 | H6: =C6*ParaFiscales!$C$24 -> 80000 | I6: =C6*ParaFiscales!$C$23 -> 240000 | J6: =SUM(H6:I6) -> 320000 | K6: 249095 | L6: =C6+K6 -> 2249095 | M6: =C6*12 -> 24000000 | N6: 11795.95
B7: Programador Junior Bilingue | C7: 2900000 | D7: 30 | E7: =C7*ParaFiscales!$C$21 -> 116000 | F7: =C7*ParaFiscales!$C$20 -> 246500 | G7: =SUM(E7:F7) -> 362500 | H7: =C7*ParaFiscales!$C$24 -> 116000 | I7: =C7*ParaFiscales!$C$23 -> 348000 | J7: =SUM(H7:I7) -> 464000 | K7: 249095 | L7: =C7+K7 -> 3149095 | M7: =C7*12 -> 34800000 | N7: 16516.23
B8: Programador Senior | C8: 6000000 | D8: 30 | E8: =C8*ParaFiscales!$C$21 -> 240000 | F8: =C8*ParaFiscales!$C$20 -> 510000 | G8: =SUM(E8:F8) -> 750000 | H8: =C8*ParaFiscales!$C$24 -> 240000 | I8: =C8*ParaFiscales!$C$23 -> 720000 | J8: =SUM(H8:I8) -> 960000 | L8: =C8+K8 -> 6000000 | M8: =C8*12 -> 72000000 | N8: 31468.53
B9: Programador Senior Bilingue | C9: 9000000 | D9: 30 | E9: =C9*ParaFiscales!$C$21 -> 360000 | F9: =C9*ParaFiscales!$C$20 -> 765000 | G9: =SUM(E9:F9) -> 1125000 | H9: =C9*ParaFiscales!$C$24 -> 360000 | I9: =C9*ParaFiscales!$C$23 -> 1080000 | J9: =SUM(H9:I9) -> 1440000 | L9: =C9+K9 -> 9000000 | M9: =C9*12 -> 108000000 | N9: 47202.8
E10: =C10*ParaFiscales!$C$21 -> 0 | F10: =C10*ParaFiscales!$C$20 -> 0 | G10: =SUM(E10:F10) -> 0 | H10: =C10*ParaFiscales!$C$24 -> 0 | I10: =C10*ParaFiscales!$C$23 -> 0 | J10: =SUM(H10:I10) -> 0 | L10: =(C10-E10-H10+K10) -> 0 | M10: =C10*12 -> 0 | N10: =D10*12 -> 0
E11: =C11*ParaFiscales!$C$21 -> 0 | F11: =C11*ParaFiscales!$C$20 -> 0 | G11: =SUM(E11:F11) -> 0 | H11: =C11*ParaFiscales!$C$24 -> 0 | I11: =C11*ParaFiscales!$C$23 -> 0 | J11: =SUM(H11:I11) -> 0 | L11: =(C11-E11-H11+K11) -> 0 | M11: =C11*12 -> 0 | N11: =D11*12 -> 0
E12: =C12*ParaFiscales!$C$21 -> 0 | F12: =C12*ParaFiscales!$C$20 -> 0 | G12: =SUM(E12:F12) -> 0 | H12: =C12*ParaFiscales!$C$24 -> 0 | I12: =C12*ParaFiscales!$C$23 -> 0 | J12: =SUM(H12:I12) -> 0 | L12: =(C12-E12-H12+K12) -> 0 | M12: =C12*12 -> 0 | N12: =D12*12 -> 0
E13: =C13*ParaFiscales!$C$21 -> 0 | F13: =C13*ParaFiscales!$C$20 -> 0 | G13: =SUM(E13:F13) -> 0 | H13: =C13*ParaFiscales!$C$24 -> 0 | I13: =C13*ParaFiscales!$C$23 -> 0 | J13: =SUM(H13:I13) -> 0 | L13: =(C13-E13-H13+K13) -> 0 | M13: =C13*12 -> 0 | N13: =D13*12 -> 0
E14: =C14*ParaFiscales!$C$21 -> 0 | F14: =C14*ParaFiscales!$C$20 -> 0 | G14: =SUM(E14:F14) -> 0 | H14: =C14*ParaFiscales!$C$24 -> 0 | I14: =C14*ParaFiscales!$C$23 -> 0 | J14: =SUM(H14:I14) -> 0 | L14: =(C14-E14-H14+K14) -> 0 | M14: =C14*12 -> 0 | N14: =D14*12 -> 0
E15: =C15*ParaFiscales!$C$21 -> 0 | F15: =C15*ParaFiscales!$C$20 -> 0 | G15: =SUM(E15:F15) -> 0 | H15: =C15*ParaFiscales!$C$24 -> 0 | I15: =C15*ParaFiscales!$C$23 -> 0 | J15: =SUM(H15:I15) -> 0 | L15: =(C15-E15-H15+K15) -> 0 | M15: =C15*12 -> 0 | N15: =D15*12 -> 0
E16: =C16*ParaFiscales!$C$21 -> 0 | F16: =C16*ParaFiscales!$C$20 -> 0 | G16: =SUM(E16:F16) -> 0 | H16: =C16*ParaFiscales!$C$24 -> 0 | I16: =C16*ParaFiscales!$C$23 -> 0 | J16: =SUM(H16:I16) -> 0 | L16: =(C16-E16-H16+K16) -> 0 | M16: =C16*12 -> 0 | N16: =D16*12 -> 0
B17: Totales | C17: =SUM(C5:C16) -> 21650905 | E17: =SUM(E5:E16) -> 866036.2 | F17: =SUM(F5:F16) -> 1840326.9 | G17: =SUM(G5:G16) -> 2706363.1 | H17: =SUM(H5:H16) -> 866036.2 | I17: =SUM(I5:I16) -> 2598108.6 | J17: =SUM(J5:J16) -> 3464144.8 | K17: =SUM(K5:K16) -> 747285 | L17: =SUM(L5:L16) -> 22398190 | ... N17: =SUM(N5:N16) -> 117473.02
B20: Aportes Fiscales Minimo | E20: Aportes Fiscales Junior | H20: Aportes Fiscales Junior B
B21: SENA | C21: =$C$5*ParaFiscales!C8 -> 35018.1 | E21: SENA | F21: =$C$6*ParaFiscales!$C$8 -> 40000 | H21: SENA | I21: =$C$7*ParaFiscales!$C$8 -> 58000
B22: ICBF | C22: =$C$5*ParaFiscales!C9 -> 52527.15 | E22: ICBF | F22: =$C$6*ParaFiscales!$C$9 -> 60000 | H22: ICBF | I22: =$C$7*ParaFiscales!$C$9 -> 87000
B23: Cajas | C23: =$C$5*ParaFiscales!C10 -> 70036.2 | E23: Cajas | F23: =$C$6*ParaFiscales!$C$10 -> 80000 | H23: Cajas | I23: =$C$7*ParaFiscales!$C$10 -> 116000
B24: Total | C24: =SUM(C21:C23) -> 157581.45 | E24: Total | F24: =SUM(F21:F23) -> 180000 | H24: Total | I24: =SUM(I21:I23) -> 261000
B25: Cargas Prestacionales | E25: Cargas Prestacionales | H25: Cargas Prestacionales
B26: Cesantias | C26: =$C$5*ParaFiscales!C13 -> 145850.39 | E26: Cesantias | F26: =$C$6*ParaFiscales!$C$13 -> 166600 | H26: Cesantias | I26: =$C$7*ParaFiscales!$C$13 -> 241570
B27: Intereses a las Cesantias | C27: =$C$5*ParaFiscales!C14 -> 17509.05 | E27: Intereses a las Cesantias | F27: =$C$6*ParaFiscales!$C$14 -> 20000 | H27: Intereses a las Cesantias | I27: =$C$7*ParaFiscales!$C$14 -> 29000
B28: Prima de Servicios | C28: =$C$5*ParaFiscales!C15 -> 145850.39 | E28: Prima de Servicios | F28: =$C$6*ParaFiscales!$C$15 -> 166600 | H28: Prima de Servicios | I28: =$C$7*ParaFiscales!$C$15 -> 241570
B29: Vacaciones | C29: =$C$5*ParaFiscales!C16 -> 73012.739 | E29: Vacaciones | F29: =$C$6*ParaFiscales!$C$16 -> 83400 | H29: Vacaciones | I29: =$C$7*ParaFiscales!$C$16 -> 120930
B30: Total | C30: =SUM(C26:C29) -> 382222.56 | E30: Total | F30: =SUM(F26:F29) -> 436600 | H30: Total | I30: =SUM(I26:I29) -> 633070
B31: Seguridad Social | E31: Seguridad Social | H31: Seguridad Social
B32: Salud | E32: Salud | H32: Salud
B33: Empresa | C33: =C$5*ParaFiscales!C20 -> 148826.92 | E33: Empresa | F33: =C$6*ParaFiscales!$C$20 -> 170000 | H33: Empresa | I33: =$C$7*ParaFiscales!$C$20 -> 246500
B34: Pension | E34: Pension | H34: Pension
B35: Empresa | C35: =C$5*ParaFiscales!C23 -> 210108.6 | E35: Empresa | F35: =C$6*ParaFiscales!$C$23 -> 240000 | H35: Empresa | I35: =$C$7*ParaFiscales!$C$23 -> 348000
B36: Totales | C36: =SUM(C24+C30+C33+C35) -> 898739.54 | E36: Totales | F36: =SUM(F24+F30+F33+F35) -> 1026600 | H36: Totales | I36: =SUM(I24+I30+I33+I35) -> 1488570
E38: Aportes Fiscales Senior | H38: Aportes Fiscales Senior B
E39: SENA | F39: =$C$8*ParaFiscales!$C$8 -> 120000 | H39: SENA | I39: =$C$9*ParaFiscales!$C$8 -> 180000
E40: ICBF | F40: =$C$8*ParaFiscales!$C$9 -> 180000 | H40: ICBF | I40: =$C$9*ParaFiscales!$C$9 -> 270000
E41: Cajas | F41: =$C$8*ParaFiscales!$C$10 -> 240000 | H41: Cajas | I41: =$C$9*ParaFiscales!$C$10 -> 360000
E42: Total | F42: =SUM(F39:F41) -> 540000 | H42: Total | I42: =SUM(I39:I41) -> 810000
E43: Cargas Prestacionales | H43: Cargas Prestacionales
E44: Cesantias | F44: =$C$8*ParaFiscales!$C$13 -> 499800 | H44: Cesantias | I44: =$C$9*ParaFiscales!$C$13 -> 749700
E45: Intereses a las Cesantias | F45: =$C$8*ParaFiscales!$C$14 -> 60000 | H45: Intereses a las Cesantias | I45: =$C$9*ParaFiscales!$C$14 -> 90000
...

Sheet Gastos Administrativos
C3: Gastos Administrativos
C4: Concepto | D4: Valor | E4: Mes 1 | F4: Total Año
C5: Arrendamiento | D5: 800000 | E5: =D5 -> 800000 | F5: =E5*12 -> 9600000
C6: Servicios Publicos | D6: 200000 | E6: =D6 -> 200000 | F6: =E6*12 -> 2400000
C7: Suministros de Oficina | D7: 80000 | E7: =D7 -> 80000 | F7: =E7*12 -> 960000
C8: Aseo e Higiene | D8: 50000 | E8: =D8 -> 50000 | F8: =E8*12 -> 600000
C9: Telefonia | D9: 90000 | E9: =D9 -> 90000 | F9: =E9*12 -> 1080000
C10: Internet | D10: 120000 | E10: =D10 -> 120000 | F10: =E10*12 -> 1440000
E11: =D11 | F11: =E11*12 -> 0
E12: =D12 | F12: =E12*12 -> 0
E13: =D13 | F13: =E13*12 -> 0
E14: =D14 | F14: =E14*12 -> 0
E15: =D15 | F15: =E15*12 -> 0
C16: Total | D16: =SUM(D5:D15) -> 1340000 | E16: =SUM(E5:E15) -> 1340000 | F16: =SUM(F5:F15) -> 16080000
C18: Gastos de Administración
C19: Concepto | D19: Año 1 | E19: Año 2 | F19: Año 3 | G19: Año 4 | H19: Año 5
C20: =C5 -> Arrendamiento | D20: =F5 -> 9600000 | E20: =(D20*'Datos Economicos'!$E$20)+D20 -> 9936000 | F20: =(E20*'Datos Economicos'!$F$20)+E20 -> 10303632 | G20: =(F20*'Datos Economicos'!$G$20)+F20 -> 10633348 | H20: =(G20*'Datos Economicos'!$H$20)+G20 -> 10962982
C21: =C6 -> Servicios Publicos | D21: =F6 -> 2400000 | E21: =(D21*'Datos Economicos'!$E$20)+D21 -> 2484000 | F21: =(E21*'Datos Economicos'!$F$20)+E21 -> 2575908 | G21: =(F21*'Datos Economicos'!$G$20)+F21 -> 2658337.1 | H21: =(G21*'Datos Economicos'!$H$20)+G21 -> 2740745.5
C22: =C7 -> Suministros de Oficina | D22: =F7 -> 960000 | E22: =(D22*'Datos Economicos'!$E$20)+D22 -> 993600 | F22: =(E22*'Datos Economicos'!$F$20)+E22 -> 1030363.2 | G22: =(F22*'Datos Economicos'!$G$20)+F22 -> 1063334.8 | H22: =(G22*'Datos Economicos'!$H$20)+G22 -> 1096298.2
C23: =C8 -> Aseo e Higiene | D23: =F8 -> 600000 | E23: =(D23*'Datos Economicos'!$E$20)+D23 -> 621000 | F23: =(E23*'Datos Economicos'!$F$20)+E23 -> 643977 | G23: =(F23*'Datos Economicos'!$G$20)+F23 -> 664584.26 | H23: =(G23*'Datos Economicos'!$H$20)+G23 -> 685186.38
C24: =C9 -> Telefonia | D24: =F9 -> 1080000 | E24: =(D24*'Datos Economicos'!$E$20)+D24 -> 1117800 | F24: =(E24*'Datos Economicos'!$F$20)+E24 -> 1159158.6 | G24: =(F24*'Datos Economicos'!$G$20)+F24 -> 1196251.7 | H24: =(G24*'Datos Economicos'!$H$20)+G24 -> 1233335.5
C25: =C10 -> Internet | D25: =F10 -> 1440000 | E25: =(D25*'Datos Economicos'!$E$20)+D25 -> 1490400 | F25: =(E25*'Datos Economicos'!$F$20)+E25 -> 1545544.8 | G25: =(F25*'Datos Economicos'!$G$20)+F25 -> 1595002.2 | H25: =(G25*'Datos Economicos'!$H$20)+G25 -> 1644447.3
C26: =C11 | D26: =F11 -> 0 | E26: =(D26*'Datos Economicos'!$E$20)+D26 -> 0 | F26: =(E26*'Datos Economicos'!$F$20)+E26 -> 0 | G26: =(F26*'Datos Economicos'!$G$20)+F26 -> 0 | H26: =(G26*'Datos Economicos'!$H$20)+G26 -> 0
C31: Total | D31: =SUM(D20:D30) -> 16080000 | E31: =SUM(E20:E30) -> 16642800 | F31: =SUM(F20:F30) -> 17258584 | G31: =SUM(G20:G30) -> 17810858 | H31: =SUM(H20:H30) -> 18362995

Sheet Gastos de Marketing
C3: Gastos Administrativos
C4: Concepto | D4: Valor | E4: Mes 1 | F4: Total Año
E5: =D5 | F5: =E5*12 -> 0
E6: =D6 | F6: =E6*12 -> 0
E7: =D7 | F7: =E7*12 -> 0
E8: =D8 | F8: =E8*12 -> 0
E9: =D9 | F9: =E9*12 -> 0
E10: =D10 | F10: =E10*12 -> 0
E11: =D11 | F11: =E11*12 -> 0
E12: =D12 | F12: =E12*12 -> 0
E13: =D13 | F13: =E13*12 -> 0
E14: =D14 | F14: =E14*12 -> 0
E15: =D15 | F15: =E15*12 -> 0
C16: Total | D16: =SUM(D5:D15) -> 0 | E16: =SUM(E5:E15) -> 0 | F16: =SUM(F5:F15) -> 0
C18: Gastos de Ventas
C19: Concepto | D19: Año 1 | E19: Año 2 | F19: Año 3 | G19: Año 4 | H19: Año 5
C20: =C5 | D20: =F5 -> 0 | E20: =(D20*'Datos Economicos'!$E$20)+D20 -> 0 | F20: =(E20*'Datos Economicos'!$F$20)+E20 -> 0 | G20: =(F20*'Datos Economicos'!$G$20)+F20 -> 0 | H20: =(G20*'Datos Economicos'!$H$20)+G20 -> 0
C21: =C6 | D21: =F6 -> 0 | E21: =(D21*'Datos Economicos'!$E$20)+D21 -> 0 | F21: =(E21*'Datos Economicos'!$F$20)+E21 -> 0 | G21: =(F21*'Datos Economicos'!$G$20)+F21 -> 0 | H21: =(G21*'Datos Economicos'!$H$20)+G21 -> 0
C22: =C7 | D22: =F7 -> 0 | E22: =(D22*'Datos Economicos'!$E$20)+D22 -> 0 | F22: =(E22*'Datos Economicos'!$F$20)+E22 -> 0 | G22: =(F22*'Datos Economicos'!$G$20)+F22 -> 0 | H22: =(G22*'Datos Economicos'!$H$20)+G22 -> 0
C31: Total | D31: =SUM(D20:D30) -> 0 | E31: =SUM(E20:E30) -> 0 | F31: =SUM(F20:F30) -> 0 | G31: =SUM(G20:G30) -> 0 | H31: =SUM(H20:H30) -> 0

Sheet Producto 1
B2: Producto | C2: ='Estructura de Mercado'!B8 -> Asistnte
B4: Costo Unitario Total
B5: Concepto | C5: Costo Unitario Año Base | D5: Año 1 | E5: Año 2 | F5: Año 3 | G5: Año 4 | H5: Año 5
B6: Materia Prima e Insumos | C6: =F28 -> 0 | D6: =C6 -> 0 | E6: =(D6*'Datos Economicos'!E21)+D6 -> 0 | F6: =(E6*'Datos Economicos'!F21)+E6 -> 0 | G6: =(F6*'Datos Economicos'!G21)+F6 -> 0 | H6: =(G6*'Datos Economicos'!H21)+G6 -> 0
B10: Total | C10: =SUM(C6:C9) -> 0 | D10: =SUM(D6:D9) -> 0 | E10: =SUM(E6:E9) -> 0 | F10: =SUM(F6:F9) -> 0 | G10: =SUM(G6:G9) -> 0 | H10: =SUM(H6:H9) -> 0
B13: Insumos
B14: Materia Prima | C14: Unidad de Medida | D14: Valor Unitario | E14: Cantidad Por unidad | F14: Total Costo Unitario
B15: MariaDb | C15: Unidad de Medida | D15: 0 | E15: 1 | F15: =D15*E15 -> 0
B16: Xammpp | C16: Unidad de Medida | D16: 0 | E16: 1 | F16: =D16*E16 -> 0
B17: Draw.io | C17: Unidad de Medida | D17: 0 | E17: 1 | F17: =D17*E17 -> 0
B18: visual studio | C18: Unidad de Medida | D18: 0 | E18: 1 | F18: =D18*E18 -> 0
B19: React | C19: Unidad de Medida | D19: 0 | E19: 1 | F19: =D19*E19 -> 0
B20: Androdi Studio | C20: Unidad de Medida | D20: 0 | E20: 1 | F20: =D20*E20 -> 0
D21: 0 | F21: =D21*E21 -> 0
D22: 0 | F22: =D22*E22 -> 0
D23: 0 | F23: =D23*E23 -> 0
D24: 0 | F24: =D24*E24 -> 0
D25: 0 | F25: =D25*E25 -> 0
D26: 0 | F26: =D26*E26 -> 0
D27: 0 | F27: =D27*E27 -> 0
B28: Sub Total | D28: =SUM(D15:D27) -> 0 | F28: =SUM(F15:F27) -> 0
B31: Mano de Obra
B32: Mano de Obra | C32: Unidad de Medida | D32: Valor Unitario | E32: Cantidad Por unidad | F32: Total Costo Unitario
B46: Sub Total | D46: =SUM(D33:D45) -> 0 | F46: =SUM(F33:F45) -> 0

Sheet Producto 2
B2: Producto
B4: Costo Unitario Total
B5: Concepto | C5: Costo Unitario Año Base | D5: Año 1 | E5: Año 2 | F5: Año 3 | G5: Año 4 | H5: Año 5
B6: Materia Prima e Insumos
B10: Total | C10: =SUM(C6:C9) -> 0 | D10: =SUM(D6:D9) -> 0 | E10: =SUM(E6:E9) -> 0 | F10: =SUM(F6:F9) -> 0 | G10: =SUM(G6:G9) -> 0 | H10: =SUM(H6:H9) -> 0
B13: Insumos
B14: Materia Prima | C14: Unidad de Medida | D14: Valor Unitario | E14: Cantidad Por unidad | F14: Total Costo Unitario
F15: =D15*E15 -> 0
F16: =D16*E16 -> 0
B28: Sub Total | D28: =SUM(D15:D27) -> 0 | F28: =SUM(F15:F27) -> 0
B31: Mano de Obra
B32: Mano de Obra | C32: Unidad de Medida | D32: Valor Unitario | E32: Cantidad Por unidad | F32: Total Costo Unitario
B46: Sub Total | D46: =SUM(D33:D45) -> 0 | F46: =SUM(F33:F45) -> 0

Sheet Producto 3
B2: Producto
B4: Costo Unitario Total
B5: Concepto | C5: Costo Unitario Año Base | D5: Año 1 | E5: Año 2 | F5: Año 3 | G5: Año 4 | H5: Año 5
B6: Materia Prima e Insumos
B10: Total | C10: =SUM(C6:C9) -> 0 | D10: =SUM(D6:D9) -> 0 | E10: =SUM(E6:E9) -> 0 | F10: =SUM(F6:F9) -> 0 | G10: =SUM(G6:G9) -> 0 | H10: =SUM(H6:H9) -> 0
B13: Insumos
B14: Materia Prima | C14: Unidad de Medida | D14: Valor Unitario | E14: Cantidad Por unidad | F14: Total Costo Unitario
F15: =D15*E15 -> 0
F16: =D16*E16 -> 0
B28: Sub Total | D28: =SUM(D15:D27) -> 0 | F28: =SUM(F15:F27) -> 0
B31: Mano de Obra
B32: Mano de Obra | C32: Unidad de Medida | D32: Valor Unitario | E32: Cantidad Por unidad | F32: Total Costo Unitario
B46: Sub Total | D46: =SUM(D33:D45) -> 0 | F46: =SUM(F33:F45) -> 0

Sheet Producto 4
B2: Producto
B4: Costo Unitario Total
B5: Concepto | C5: Costo Unitario Año Base | D5: Año 1 | E5: Año 2 | F5: Año 3 | G5: Año 4 | H5: Año 5
B6: Materia Prima e Insumos
B10: Total | C10: =SUM(C6:C9) -> 0 | D10: =SUM(D6:D9) -> 0 | E10: =SUM(E6:E9) -> 0 | F10: =SUM(F6:F9) -> 0 | G10: =SUM(G6:G9) -> 0 | H10: =SUM(H6:H9) -> 0
B13: Insumos
B14: Materia Prima | C14: Unidad de Medida | D14: Valor Unitario | E14: Cantidad Por unidad | F14: Total Costo Unitario
F15: =D15*E15 -> 0
F16: =D16*E16 -> 0
B28: Sub Total | D28: =SUM(D15:D27) -> 0 | F28: =SUM(F15:F27) -> 0
B31: Mano de Obra
B32: Mano de Obra | C32: Unidad de Medida | D32: Valor Unitario | E32: Cantidad Por unidad | F32: Total Costo Unitario
B46: Sub Total | D46: =SUM(D33:D45) -> 0 | F46: =SUM(F33:F45) -> 0

Sheet Comportamiento de Ventas
B2: Unidades a Producir | E2: Calificación de Comportamiento | F2: Calificación
B3: Producto | C3: Unidades en el Año | E3: Muy Alto | F3: 9
B4: ='Estructura de Mercado'!B8 -> Asistnte | C4: ='Estructura de Mercado'!G8 -> 12 | E4: Alto | F4: 7
E5: Normal | F5: 5
E6: Bajo | F6: 3
E7: Sin Ventas | F7: 0
B9: Total | C9: =SUM(C4:C8) -> 12 | E9: Ventas Anuales | F9: ='Datos Economicos'!F6 -> 44000000
B12: Meses | C12: Calificación | D12: Año 1
D13: Unidades | E13: Ventas
B14: Enero | C14: 3 | D14: =IF($C$26>0,(C14/$C$26)*$C$9,0) -> 0.69230769 | E14: =IF($D$26>0,($F$9*D14)/$D$26,) -> 2538461.5
B15: Febrero | C15: 5 | D15: =IF($C$26>0,(C15/$C$26)*$C$9,0) -> 1.1538462 | E15: =IF($D$26>0,($F$9*D15)/$D$26,) -> 4230769.2
B16: Marzo | C16: 5 | D16: =IF($C$26>0,(C16/$C$26)*$C$9,0) -> 1.1538462 | E16: =IF($D$26>0,($F$9*D16)/$D$26,) -> 4230769.2
B17: Abril | C17: 5 | D17: =IF($C$26>0,(C17/$C$26)*$C$9,0) -> 1.1538462 | E17: =IF($D$26>0,($F$9*D17)/$D$26,) -> 4230769.2
B18: Mayo | C18: 5 | D18: =IF($C$26>0,(C18/$C$26)*$C$9,0) -> 1.1538462 | E18: =IF($D$26>0,($F$9*D18)/$D$26,) -> 4230769.2
B19: Junio | C19: 3 | D19: =IF($C$26>0,(C19/$C$26)*$C$9,0) -> 0.69230769 | E19: =IF($D$26>0,($F$9*D19)/$D$26,) -> 2538461.5
B20: Julio | C20: 3 | D20: =IF($C$26>0,(C20/$C$26)*$C$9,0) -> 0.69230769 | E20: =IF($D$26>0,($F$9*D20)/$D$26,) -> 2538461.5
B21: Agosto | C21: 5 | D21: =IF($C$26>0,(C21/$C$26)*$C$9,0) -> 1.1538462 | E21: =IF($D$26>0,($F$9*D21)/$D$26,) -> 4230769.2
B22: Septiembre | C22: 5 | D22: =IF($C$26>0,(C22/$C$26)*$C$9,0) -> 1.1538462 | E22: =IF($D$26>0,($F$9*D22)/$D$26,) -> 4230769.2
B23: Octubre | C23: 5 | D23: =IF($C$26>0,(C23/$C$26)*$C$9,0) -> 1.1538462 | E23: =IF($D$26>0,($F$9*D23)/$D$26,) -> 4230769.2
B24: Noviembre | C24: 5 | D24: =IF($C$26>0,(C24/$C$26)*$C$9,0) -> 1.1538462 | E24: =IF($D$26>0,($F$9*D24)/$D$26,) -> 4230769.2
B25: Diciembre | C25: 3 | D25: =IF($C$26>0,(C25/$C$26)*$C$9,0) -> 0.69230769 | E25: =IF($D$26>0,($F$9*D25)/$D$26,) -> 2538461.5
B26: Total | C26: =SUM(C14:C25) -> 52 | D26: =SUM(D14:D25) -> 12 | E26: =SUM(E14:E25) -> 44000000

Sheet Comportamiento de Compras
B2: Unidades a Producir | E2: Calificación de Comportamiento | F2: Calificación | H2: Producto | I2: Total Costos
B3: Producto | C3: Unidades en el Año | E3: Muy Alto | F3: 9 | H3: ='Producto 1'!C2:H2 | I3: ='Producto 1'!C10 -> 0
B4: ='Estructura de Mercado'!B8 -> Asistnte | C4: ='Estructura de Mercado'!G8 -> 12 | E4: Alto | F4: 7 | H4: ='Producto 2'!C2:H2 | I4: ='Producto 2'!C10 -> 0
E5: Normal | F5: 5 | H5: ='Producto 3'!C2:H2 | I5: ='Producto 3'!C10 -> 0
E6: Bajo | F6: 3 | H6: ='Producto 4'!C2:H2 | I6: ='Producto 4'!C10 -> 0
E7: Sin Ventas | F7: 0
B9: Total | C9: =SUM(C4:C8) -> 12 | E9: Costos Anuales | F9: =SUM(I3:I6) -> 0
B12: Meses | C12: Calificación | D12: Año 1
D13: Unidades | E13: Ventas
B14: Enero | C14: 3 | D14: =IF($C$26>0,(C14/$C$26)*$C$9,0) -> 0.64285714 | E14: =IF($D$26>0,($F$9*D14)/$D$26,) -> 0
B15: Febrero | C15: 3 | D15: =IF($C$26>0,(C15/$C$26)*$C$9,0) -> 0.64285714 | E15: =IF($D$26>0,($F$9*D15)/$D$26,) -> 0
B16: Marzo | C16: 5 | D16: =IF($C$26>0,(C16/$C$26)*$C$9,0) -> 1.0714286 | E16: =IF($D$26>0,($F$9*D16)/$D$26,) -> 0
B17: Abril | C17: 5 | D17: =IF($C$26>0,(C17/$C$26)*$C$9,0) -> 1.0714286 | E17: =IF($D$26>0,($F$9*D17)/$D$26,) -> 0
B18: Mayo | C18: 5 | D18: =IF($C$26>0,(C18/$C$26)*$C$9,0) -> 1.0714286 | E18: =IF($D$26>0,($F$9*D18)/$D$26,) -> 0
B19: Junio | C19: 5 | D19: =IF($C$26>0,(C19/$C$26)*$C$9,0) -> 1.0714286 | E19: =IF($D$26>0,($F$9*D19)/$D$26,) -> 0
B20: Julio | C20: 5 | D20: =IF($C$26>0,(C20/$C$26)*$C$9,0) -> 1.0714286 | E20: =IF($D$26>0,($F$9*D20)/$D$26,) -> 0
B21: Agosto | C21: 5 | D21: =IF($C$26>0,(C21/$C$26)*$C$9,0) -> 1.0714286 | E21: =IF($D$26>0,($F$9*D21)/$D$26,) -> 0
B22: Septiembre | C22: 5 | D22: =IF($C$26>0,(C22/$C$26)*$C$9,0) -> 1.0714286 | E22: =IF($D$26>0,($F$9*D22)/$D$26,) -> 0
B23: Octubre | C23: 5 | D23: =IF($C$26>0,(C23/$C$26)*$C$9,0) -> 1.0714286 | E23: =IF($D$26>0,($F$9*D23)/$D$26,) -> 0
B24: Noviembre | C24: 5 | D24: =IF($C$26>0,(C24/$C$26)*$C$9,0) -> 1.0714286 | E24: =IF($D$26>0,($F$9*D24)/$D$26,) -> 0
B25: Diciembre | C25: 5 | D25: =IF($C$26>0,(C25/$C$26)*$C$9,0) -> 1.0714286 | E25: =IF($D$26>0,($F$9*D25)/$D$26,) -> 0
B26: Total | C26: =SUM(C14:C25) -> 56 | D26: =SUM(D14:D25) -> 12 | E26: =SUM(E14:E25) -> 0

Sheet Costos del Proyecto
C4: Costo Inicial del Proyecto
C5: Concepto | D5: Valor
C6: Gastos de Constitucion | D6: =SUM('Gastos de Constitución'!E11+'Gastos de Constitución'!E21) -> 0
C7: Plan de Inversión | D7: ='Plan de Inversion'!I8 -> 8020232
C8: Gastos de Personal | D8: ='Gastos de Personal'!C17 -> 21650905
C9: Parafiscales | D9: ='Gastos de Personal'!C36 -> 898739.54
C10: Gastos Administrativos | D10: ='Gastos Administrativos'!D16 -> 1340000
C11: Gastos de Marketing | D11: ='Gastos de Marketing'!D16 -> 0
C12: Costos de Insumos | D12: ='Comportamiento de Compras'!F9 -> 0
C13: Total | D13: =SUM(D6:D12) -> 31909877
